<?xml version="1.0" ?>
<!-- This file was generated by robot assembler -->
<robot name="rarm"
       xmlns:xi="http://www.w3.org/2001/XInclude"
       xmlns:gazebo="http://playerstage.sourceforge.net/gazebo/xmlschema/#gz"
       xmlns:model="http://playerstage.sourceforge.net/gazebo/xmlschema/#model"
       xmlns:sensor="http://playerstage.sourceforge.net/gazebo/xmlschema/#sensor"
       xmlns:body="http://playerstage.sourceforge.net/gazebo/xmlschema/#body"
       xmlns:geom="http://playerstage.sourceforge.net/gazebo/xmlschema/#geom"
       xmlns:joint="http://playerstage.sourceforge.net/gazebo/xmlschema/#joint"
       xmlns:interface="http://playerstage.sourceforge.net/gazebo/xmlschema/#interface"
       xmlns:rendering="http://playerstage.sourceforge.net/gazebo/xmlschema/#rendering"
       xmlns:renderable="http://playerstage.sourceforge.net/gazebo/xmlschema/#renderable"
       xmlns:controller="http://playerstage.sourceforge.net/gazebo/xmlschema/#controller"
       xmlns:physics="http://playerstage.sourceforge.net/gazebo/xmlschema/#physics"
       xmlns:xacro="http://www.ros.org/wiki/xacro">
  <xacro:macro name="gazebo_link_reference" params="link_name mu1:=0.9 mu2:=0.9" >
    <gazebo reference="${link_name}">
      <mu1>${mu1}</mu1>
      <mu2>${mu2}</mu2>
    </gazebo>
  </xacro:macro>
  <xacro:macro name="gazebo_transmission" params="joint_name" >
    <transmission name="${joint_name}_trans">
      <type>transmission_interface/SimpleTransmission</type>
      <joint name="${joint_name}">
        <hardwareInterface>hardware_interface/VelocityJointInterface</hardwareInterface>
        <!--hardwareInterface>hardware_interface/EffortJointInterface</hardwareInterface-->
      </joint>
      <actuator name="${joint_name}_motor">
        <hardwareInterface>hardware_interface/VelocityJointInterface</hardwareInterface>
        <!--hardwareInterface>hardware_interface/EffortJointInterface</hardwareInterface-->
        <mechanicalReduction>1</mechanicalReduction>
      </actuator>
    </transmission>
  </xacro:macro>

  <xacro:macro name="no_gazebo_transmission" params="joint_name" >
    <!-- dummy for fixed joint -->
  </xacro:macro>
  <xacro:gazebo_link_reference link_name="BASE" />
  <link name="BASE">
  <inertial>
     <mass value="0.011949"/>
     <origin rpy="0 0 0" xyz="2.973231e-18 4.461323e-18 0.007918"/>
     <inertia ixx="1.701549e-06" ixy="9.249566e-22" ixz="-1.136868e-22" iyy="3.250821e-06" iyz="-6.644882e-22" izz="2.468319e-06"/>
  </inertial>
  <visual>
     <origin xyz="0.000000 0.000000 0.000000" rpy="0.00000000 -0.00000000 0.00000000"/>
     <geometry>
     <mesh filename="package://robot_assembler/meshes/mesh_JOINT-BASE.dae" scale="1.000000 1.000000 1.000000"/>
     </geometry>
  </visual>
  <collision>
     <origin xyz="0.000000 0.000000 0.000000" rpy="0.00000000 -0.00000000 0.00000000"/>
     <geometry>
     <mesh filename="package://robot_assembler/meshes/mesh_JOINT-BASE.dae" scale="1.000000 1.000000 1.000000"/>
     </geometry>
  </collision>
  <visual>
     <origin xyz="-0.013000 0.000000 -0.000000" rpy="0.00000000 -0.00000000 -3.14159265"/>
     <geometry>
     <mesh filename="package://robot_assembler/meshes/mesh_BOTTOM-ARM26.dae" scale="1.000000 1.000000 1.000000"/>
     </geometry>
  </visual>
  <collision>
     <origin xyz="-0.013000 0.000000 -0.000000" rpy="0.00000000 -0.00000000 -3.14159265"/>
     <geometry>
     <mesh filename="package://robot_assembler/meshes/mesh_BOTTOM-ARM26.dae" scale="1.000000 1.000000 1.000000"/>
     </geometry>
  </collision>
  <visual>
     <origin xyz="0.013000 0.000000 0.000000" rpy="0.00000000 -0.00000000 0.00000000"/>
     <geometry>
     <mesh filename="package://robot_assembler/meshes/mesh_UPPER-ARM26.dae" scale="1.000000 1.000000 1.000000"/>
     </geometry>
  </visual>
  <collision>
     <origin xyz="0.013000 0.000000 0.000000" rpy="0.00000000 -0.00000000 0.00000000"/>
     <geometry>
     <mesh filename="package://robot_assembler/meshes/mesh_UPPER-ARM26.dae" scale="1.000000 1.000000 1.000000"/>
     </geometry>
  </collision>
  </link>
  <xacro:gazebo_link_reference link_name="LINK0" />
  <link name="LINK0">
  <inertial>
     <mass value="0.068898"/>
     <origin rpy="0 0 0" xyz="-0.02723 -0.000531 -0.018"/>
     <inertia ixx="0.002003" ixy="-3.115518e-07" ixz="1.016076e-21" iyy="0.002038" iyz="1.017852e-21" izz="0.002038"/>
  </inertial>
  <visual>
     <origin xyz="0.000000 0.000000 -0.018000" rpy="0.00000000 -0.00000000 -3.14159265"/>
     <geometry>
     <mesh filename="package://robot_assembler/meshes/mesh_SERVO-S3301.dae" scale="1.000000 1.000000 1.000000"/>
     </geometry>
  </visual>
  <collision>
     <origin xyz="0.000000 0.000000 -0.018000" rpy="0.00000000 -0.00000000 -3.14159265"/>
     <geometry>
     <mesh filename="package://robot_assembler/meshes/mesh_SERVO-S3301.dae" scale="1.000000 1.000000 1.000000"/>
     </geometry>
  </collision>
  <visual>
     <origin xyz="-0.030000 -0.000000 -0.005000" rpy="0.78539816 -1.57079633 -2.35619449"/>
     <geometry>
     <mesh filename="package://robot_assembler/meshes/mesh_JOINT-FRAME-A.dae" scale="1.000000 1.000000 1.000000"/>
     </geometry>
  </visual>
  <collision>
     <origin xyz="-0.030000 -0.000000 -0.005000" rpy="0.78539816 -1.57079633 -2.35619449"/>
     <geometry>
     <mesh filename="package://robot_assembler/meshes/mesh_JOINT-FRAME-A.dae" scale="1.000000 1.000000 1.000000"/>
     </geometry>
  </collision>
  <visual>
     <origin xyz="-0.030000 -0.000000 -0.018000" rpy="-1.02404522 -1.57079633 -2.11754743"/>
     <geometry>
     <mesh filename="package://robot_assembler/meshes/mesh_JOINT-BASE.dae" scale="1.000000 1.000000 1.000000"/>
     </geometry>
  </visual>
  <collision>
     <origin xyz="-0.030000 -0.000000 -0.018000" rpy="-1.02404522 -1.57079633 -2.11754743"/>
     <geometry>
     <mesh filename="package://robot_assembler/meshes/mesh_JOINT-BASE.dae" scale="1.000000 1.000000 1.000000"/>
     </geometry>
  </collision>
  <visual>
     <origin xyz="-0.039000 -0.021000 -0.018000" rpy="-1.57079633 -0.00000000 0.00000000"/>
     <geometry>
     <mesh filename="package://robot_assembler/meshes/mesh_BOTTOM-SPACER.dae" scale="1.000000 1.000000 1.000000"/>
     </geometry>
  </visual>
  <collision>
     <origin xyz="-0.039000 -0.021000 -0.018000" rpy="-1.57079633 -0.00000000 0.00000000"/>
     <geometry>
     <mesh filename="package://robot_assembler/meshes/mesh_BOTTOM-SPACER.dae" scale="1.000000 1.000000 1.000000"/>
     </geometry>
  </collision>
  <visual>
     <origin xyz="-0.052000 -0.000000 -0.018000" rpy="1.57079633 0.00000000 -1.57079633"/>
     <geometry>
     <mesh filename="package://robot_assembler/meshes/mesh_SERVO-S3301.dae" scale="1.000000 1.000000 1.000000"/>
     </geometry>
  </visual>
  <collision>
     <origin xyz="-0.052000 -0.000000 -0.018000" rpy="1.57079633 0.00000000 -1.57079633"/>
     <geometry>
     <mesh filename="package://robot_assembler/meshes/mesh_SERVO-S3301.dae" scale="1.000000 1.000000 1.000000"/>
     </geometry>
  </collision>
  <visual>
     <origin xyz="-0.030000 -0.000000 -0.031000" rpy="2.25398777 1.57079633 0.68319145"/>
     <geometry>
     <mesh filename="package://robot_assembler/meshes/mesh_JOINT-FRAME-A.dae" scale="1.000000 1.000000 1.000000"/>
     </geometry>
  </visual>
  <collision>
     <origin xyz="-0.030000 -0.000000 -0.031000" rpy="2.25398777 1.57079633 0.68319145"/>
     <geometry>
     <mesh filename="package://robot_assembler/meshes/mesh_JOINT-FRAME-A.dae" scale="1.000000 1.000000 1.000000"/>
     </geometry>
  </collision>
  </link>
  <xacro:gazebo_link_reference link_name="LINK1" />
  <link name="LINK1">
  <inertial>
     <mass value="0.011949"/>
     <origin rpy="0 0 0" xyz="4.757170e-18 5.532881e-18 0.010418"/>
     <inertia ixx="1.701549e-06" ixy="1.491902e-21" ixz="-6.821210e-22" iyy="3.250821e-06" iyz="-7.675530e-22" izz="2.468319e-06"/>
  </inertial>
  <visual>
     <origin xyz="0.000000 -0.000000 0.002500" rpy="0.00000000 -0.00000000 0.00000000"/>
     <geometry>
     <mesh filename="package://robot_assembler/meshes/mesh_JOINT-BASE.dae" scale="1.000000 1.000000 1.000000"/>
     </geometry>
  </visual>
  <collision>
     <origin xyz="0.000000 -0.000000 0.002500" rpy="0.00000000 -0.00000000 0.00000000"/>
     <geometry>
     <mesh filename="package://robot_assembler/meshes/mesh_JOINT-BASE.dae" scale="1.000000 1.000000 1.000000"/>
     </geometry>
  </collision>
  <visual>
     <origin xyz="-0.013000 0.000000 0.002500" rpy="0.00000000 -0.00000000 -3.14159265"/>
     <geometry>
     <mesh filename="package://robot_assembler/meshes/mesh_BOTTOM-ARM26.dae" scale="1.000000 1.000000 1.000000"/>
     </geometry>
  </visual>
  <collision>
     <origin xyz="-0.013000 0.000000 0.002500" rpy="0.00000000 -0.00000000 -3.14159265"/>
     <geometry>
     <mesh filename="package://robot_assembler/meshes/mesh_BOTTOM-ARM26.dae" scale="1.000000 1.000000 1.000000"/>
     </geometry>
  </collision>
  <visual>
     <origin xyz="0.013000 -0.000000 0.002500" rpy="0.00000000 0.00000000 0.00000000"/>
     <geometry>
     <mesh filename="package://robot_assembler/meshes/mesh_UPPER-ARM26.dae" scale="1.000000 1.000000 1.000000"/>
     </geometry>
  </visual>
  <collision>
     <origin xyz="0.013000 -0.000000 0.002500" rpy="0.00000000 0.00000000 0.00000000"/>
     <geometry>
     <mesh filename="package://robot_assembler/meshes/mesh_UPPER-ARM26.dae" scale="1.000000 1.000000 1.000000"/>
     </geometry>
  </collision>
  </link>
  <xacro:gazebo_link_reference link_name="LINK2" />
  <link name="LINK2">
  <inertial>
     <mass value="0.071723"/>
     <origin rpy="0 0 0" xyz="-0.029208 9.585489e-07 -0.018337"/>
     <inertia ixx="0.002004" ixy="8.106716e-10" ixz="-2.847049e-07" iyy="0.002044" iyz="3.377936e-10" izz="0.002044"/>
  </inertial>
  <visual>
     <origin xyz="0.000000 0.000000 -0.018000" rpy="0.00000000 -0.00000000 -3.14159265"/>
     <geometry>
     <mesh filename="package://robot_assembler/meshes/mesh_SERVO-S3301.dae" scale="1.000000 1.000000 1.000000"/>
     </geometry>
  </visual>
  <collision>
     <origin xyz="0.000000 0.000000 -0.018000" rpy="0.00000000 -0.00000000 -3.14159265"/>
     <geometry>
     <mesh filename="package://robot_assembler/meshes/mesh_SERVO-S3301.dae" scale="1.000000 1.000000 1.000000"/>
     </geometry>
  </collision>
  <visual>
     <origin xyz="-0.030000 -0.000000 -0.031000" rpy="-2.89661399 1.57079633 1.81577499"/>
     <geometry>
     <mesh filename="package://robot_assembler/meshes/mesh_JOINT-FRAME-A.dae" scale="1.000000 1.000000 1.000000"/>
     </geometry>
  </visual>
  <collision>
     <origin xyz="-0.030000 -0.000000 -0.031000" rpy="-2.89661399 1.57079633 1.81577499"/>
     <geometry>
     <mesh filename="package://robot_assembler/meshes/mesh_JOINT-FRAME-A.dae" scale="1.000000 1.000000 1.000000"/>
     </geometry>
  </collision>
  <visual>
     <origin xyz="-0.030000 -0.000000 -0.018000" rpy="1.57079633 -0.00000000 1.57079633"/>
     <geometry>
     <mesh filename="package://robot_assembler/meshes/mesh_JOINT-BASE.dae" scale="1.000000 1.000000 1.000000"/>
     </geometry>
  </visual>
  <collision>
     <origin xyz="-0.030000 -0.000000 -0.018000" rpy="1.57079633 -0.00000000 1.57079633"/>
     <geometry>
     <mesh filename="package://robot_assembler/meshes/mesh_JOINT-BASE.dae" scale="1.000000 1.000000 1.000000"/>
     </geometry>
  </collision>
  <visual>
     <origin xyz="-0.036000 -0.000000 -0.018000" rpy="-1.57079633 -0.00000000 1.57079633"/>
     <geometry>
     <mesh filename="package://robot_assembler/meshes/mesh_JOINT-BASE.dae" scale="1.000000 1.000000 1.000000"/>
     </geometry>
  </visual>
  <collision>
     <origin xyz="-0.036000 -0.000000 -0.018000" rpy="-1.57079633 -0.00000000 1.57079633"/>
     <geometry>
     <mesh filename="package://robot_assembler/meshes/mesh_JOINT-BASE.dae" scale="1.000000 1.000000 1.000000"/>
     </geometry>
  </collision>
  <visual>
     <origin xyz="-0.036000 -0.013000 -0.018000" rpy="3.14159265 0.00000000 -1.57079633"/>
     <geometry>
     <mesh filename="package://robot_assembler/meshes/mesh_JOINT-FRAME-B-A.dae" scale="1.000000 1.000000 1.000000"/>
     </geometry>
  </visual>
  <collision>
     <origin xyz="-0.036000 -0.013000 -0.018000" rpy="3.14159265 0.00000000 -1.57079633"/>
     <geometry>
     <mesh filename="package://robot_assembler/meshes/mesh_JOINT-FRAME-B-A.dae" scale="1.000000 1.000000 1.000000"/>
     </geometry>
  </collision>
  <visual>
     <origin xyz="-0.055500 -0.000000 -0.018000" rpy="-2.65711472 1.57079633 2.05527426"/>
     <geometry>
     <mesh filename="package://robot_assembler/meshes/mesh_SERVO-S3301.dae" scale="1.000000 1.000000 1.000000"/>
     </geometry>
  </visual>
  <collision>
     <origin xyz="-0.055500 -0.000000 -0.018000" rpy="-2.65711472 1.57079633 2.05527426"/>
     <geometry>
     <mesh filename="package://robot_assembler/meshes/mesh_SERVO-S3301.dae" scale="1.000000 1.000000 1.000000"/>
     </geometry>
  </collision>
  <visual>
     <origin xyz="-0.036000 0.013000 -0.018000" rpy="0.00000000 -0.00000000 1.57079633"/>
     <geometry>
     <mesh filename="package://robot_assembler/meshes/mesh_JOINT-FRAME-B-B.dae" scale="1.000000 1.000000 1.000000"/>
     </geometry>
  </visual>
  <collision>
     <origin xyz="-0.036000 0.013000 -0.018000" rpy="0.00000000 -0.00000000 1.57079633"/>
     <geometry>
     <mesh filename="package://robot_assembler/meshes/mesh_JOINT-FRAME-B-B.dae" scale="1.000000 1.000000 1.000000"/>
     </geometry>
  </collision>
  <visual>
     <origin xyz="-0.030000 -0.000000 -0.005000" rpy="2.35619449 -1.57079633 2.35619449"/>
     <geometry>
     <mesh filename="package://robot_assembler/meshes/mesh_JOINT-FRAME-A.dae" scale="1.000000 1.000000 1.000000"/>
     </geometry>
  </visual>
  <collision>
     <origin xyz="-0.030000 -0.000000 -0.005000" rpy="2.35619449 -1.57079633 2.35619449"/>
     <geometry>
     <mesh filename="package://robot_assembler/meshes/mesh_JOINT-FRAME-A.dae" scale="1.000000 1.000000 1.000000"/>
     </geometry>
  </collision>
  </link>
  <xacro:gazebo_link_reference link_name="LINK3" />
  <link name="LINK3">
  <inertial>
     <mass value="0.013908"/>
     <origin rpy="0 0 0" xyz="0.007157 0.01431 -0.018"/>
     <inertia ixx="5.038421e-06" ixy="-1.246318e-06" ixz="-5.303385e-22" iyy="3.169617e-06" iyz="-1.152466e-21" izz="4.682360e-06"/>
  </inertial>
  <visual>
     <origin xyz="0.000000 0.000000 -0.033500" rpy="1.53168710 1.57079633 1.06795312"/>
     <geometry>
     <mesh filename="package://robot_assembler/meshes/mesh_FINGER.dae" scale="1.000000 1.000000 1.000000"/>
     </geometry>
  </visual>
  <collision>
     <origin xyz="0.000000 0.000000 -0.033500" rpy="1.53168710 1.57079633 1.06795312"/>
     <geometry>
     <mesh filename="package://robot_assembler/meshes/mesh_FINGER.dae" scale="1.000000 1.000000 1.000000"/>
     </geometry>
  </collision>
  </link>
  <xacro:gazebo_link_reference link_name="LINK4" />
  <link name="LINK4">
  <inertial>
     <mass value="0.013908"/>
     <origin rpy="0 0 0" xyz="0.007157 0.01431 -0.018"/>
     <inertia ixx="5.038421e-06" ixy="-1.246318e-06" ixz="-2.159831e-22" iyy="3.169617e-06" iyz="2.360056e-22" izz="4.682360e-06"/>
  </inertial>
  <visual>
     <origin xyz="-0.000000 0.000000 -0.002500" rpy="-0.01815670 -1.57079633 -0.44557729"/>
     <geometry>
     <mesh filename="package://robot_assembler/meshes/mesh_FINGER.dae" scale="1.000000 1.000000 1.000000"/>
     </geometry>
  </visual>
  <collision>
     <origin xyz="-0.000000 0.000000 -0.002500" rpy="-0.01815670 -1.57079633 -0.44557729"/>
     <geometry>
     <mesh filename="package://robot_assembler/meshes/mesh_FINGER.dae" scale="1.000000 1.000000 1.000000"/>
     </geometry>
  </collision>
  </link>
  <xacro:gazebo_transmission joint_name="JOINT0" />
  <joint name="JOINT0" type="revolute">
     <parent link="BASE"/>
     <child link="LINK0"/>
     <origin xyz="0.017500 0.000000 0.023000" rpy="0.00000000 1.57079633 0.00000000"/>
     <axis xyz="0 0 1"/>
     <limit effort="200" lower="-3.14159" upper="3.14159" velocity="40"/>
  </joint>
  <xacro:gazebo_transmission joint_name="JOINT1" />
  <joint name="JOINT1" type="revolute">
     <parent link="LINK0"/>
     <child link="LINK1"/>
     <origin xyz="-0.070000 -0.000000 -0.018000" rpy="-1.57079633 -0.00000000 1.57079633"/>
     <axis xyz="0 0 1"/>
     <limit effort="200" lower="-3.14159" upper="3.14159" velocity="40"/>
  </joint>
  <xacro:gazebo_transmission joint_name="JOINT2" />
  <joint name="JOINT2" type="revolute">
     <parent link="LINK1"/>
     <child link="LINK2"/>
     <origin xyz="0.017500 -0.000000 0.025500" rpy="0.81482692 1.57079633 0.81482692"/>
     <axis xyz="0 0 1"/>
     <limit effort="200" lower="-3.14159" upper="3.14159" velocity="40"/>
  </joint>
  <xacro:gazebo_transmission joint_name="JOINT3" />
  <joint name="JOINT3" type="revolute">
     <parent link="LINK2"/>
     <child link="LINK3"/>
     <origin xyz="-0.055500 -0.018000 -0.018000" rpy="2.12939564 -1.57079633 -0.55859932"/>
     <axis xyz="0 0 1"/>
     <limit effort="200" lower="-3.14159" upper="3.14159" velocity="40"/>
  </joint>
  <xacro:gazebo_transmission joint_name="JOINT4" />
  <joint name="JOINT4" type="revolute">
     <parent link="LINK2"/>
     <child link="LINK4"/>
     <origin xyz="-0.066000 -0.018000 -0.039000" rpy="2.12939564 -1.57079633 -0.55859932"/>
     <axis xyz="0 0 1"/>
     <limit effort="200" lower="-3.14159" upper="3.14159" velocity="40"/>
  </joint>

  <!-- Gazebo plugin for ROS Control -->
  <gazebo>
    <plugin name="gazebo_ros_control" filename="libgazebo_ros_control.so">
      <!--robotNamespace>/</robotNamespace-->
      <legacyModeNS>false</legacyModeNS>
      <robotSimType>gazebo_ros_control/DefaultRobotHWSim</robotSimType>
    </plugin>
  </gazebo>
</robot>
